<?xml version="1.0"?>
<robot name="perfbalanced">
    <link name="base_link">
        <visual>
            <origin xyz="0 0 0.3"/>
            <geometry>
                <box size="0.2 0.1 0.4"/>
            </geometry>
        </visual>
        <collision>
            <origin xyz="0 0 0.3"/>
            <geometry>
                <box size="0.2 0.1 0.4"/>
            </geometry>
        </collision>
        <inertial>
            <origin xyz="0 0 0.3"/>
            <mass value="1.0"/>
            <inertia ixx="0.005" ixy="0" ixz="0" iyy="0.005" iyz="0" izz="0.005"/>
        </inertial>
    </link>
    <link name="left_wheel">
        <visual>
            <origin xyz="0 0 0" rpy="1.57 0.0 1.57 "/>
            <geometry>
                <cylinder radius="0.1" length="0.1"/>
            </geometry>
        </visual>
        <collision>
            <origin xyz="0 0 0" rpy="1.57 0.0 1.57 "/>
            <geometry>
                <cylinder radius="0.1" length="0.1"/>
            </geometry>
        </collision>
        <inertial>
            <origin xyz="0 0 0"/>
            <mass value="0.2"/>
            <inertia ixx="0.005" ixy="0" ixz="0" iyy="0.005" iyz="0" izz="0.005"/>
        </inertial>
    </link>
    <joint name="left_joint" type="continuous">
        <parent link="base_link"/>
        <child link="left_wheel"/>
        <origin xyz="-0.21 0.0 0.1"/>
        <axis xyz="1.0 0.0 0.0"/>
        <limit effort="1000" velocity="10"/>
        <dynamics damping="0.0" friction="0.0"/>
    </joint>

    <link name="right_wheel">
        <visual>
            <origin xyz="0 0 0" rpy="1.57 0.0 1.57 "/>
            <geometry>
                <cylinder radius="0.1" length="0.1"/>
            </geometry>
        </visual>
        <collision>
            <origin xyz="0 0 0" rpy="1.57 0.0 1.57 "/>
            <geometry>
                <cylinder radius="0.1" length="0.1"/>
            </geometry>
        </collision>
        <inertial>
            <origin xyz="0 0 0"/>
            <mass value="0.2"/>
            <inertia ixx="0.005" ixy="0" ixz="0" iyy="0.005" iyz="0" izz="0.005"/>
        </inertial>
    </link>
    <joint name="right_joint" type="continuous">
        <parent link="base_link"/>
        <child link="right_wheel"/>
        <origin xyz="0.21 0.0 0.1"/>
        <axis xyz="1.0 0.0 0.0"/>
        <limit effort="1000" velocity="10"/>
        <dynamics damping="0.0" friction="0.0"/>
    </joint>

</robot>